#!/usr/bin/env python3
"""
Error handling and retry test cases for PM recovery.
Tests various failure scenarios and retry logic.
"""

import json
import threading
import time
from pathlib import Path
from unittest.mock import Mock, patch

import pytest

from tmux_orchestrator.core.monitor import IdleMonitor

# TMUXManager import removed - using comprehensive_mock_tmux fixture


class ErrorHandlingRetryTest:
    """Test suite for error handling and retry logic in PM recovery."""

    def __init__(self):
        # TMUXManager removed - tests will use comprehensive_mock_tmux fixture
        self.test_sessions = []

    def setup_method(self):
        """Setup for each test."""
        self.cleanup()

    def teardown_method(self):
        """Cleanup after each test."""
        self.cleanup()

    def cleanup(self):
        """Clean up test environment."""
        for session in self.test_sessions:
            try:
                self.tmux.kill_session(session)
            except Exception:
                pass
        self.test_sessions.clear()

    def test_spawn_command_permission_error(self):
        """Test handling of permission errors during PM spawn."""
        monitor = IdleMonitor(Mock())

        with (
            patch.object(monitor, "_log_error") as mock_log,
            patch.object(monitor, "_escalate_recovery_failure") as mock_escalate,
        ):
            # Mock spawn command that fails with permission error
            def mock_spawn_with_permission_error(*args, **kwargs):
                raise PermissionError("Permission denied: cannot create tmux session")

            with patch.object(monitor, "_execute_spawn_command", side_effect=mock_spawn_with_permission_error):
                if hasattr(monitor, "_spawn_pm_with_retry"):
                    result = monitor._spawn_pm_with_retry("test:1", max_retries=3)

                    # Should fail after retries
                    assert result is None or result is False

                    # Should log the error
                    assert mock_log.called
                    error_calls = [call for call in mock_log.call_args_list if "Permission denied" in str(call)]
                    assert len(error_calls) > 0

                    # Should escalate after max retries
                    assert mock_escalate.called

                else:
                    pytest.skip("_spawn_pm_with_retry not yet implemented")

    def test_resource_exhaustion_handling(self):
        """Test handling of resource exhaustion errors."""
        monitor = IdleMonitor(Mock())

        # Simulate different resource errors
        resource_errors = [
            OSError("Cannot allocate memory"),
            OSError("No space left on device"),
            OSError("Too many open files"),
            Exception("Resource temporarily unavailable"),
        ]

        for error in resource_errors:
            with (
                patch.object(monitor, "_log_error") as mock_log,
                patch.object(monitor, "_wait_for_resources") as mock_wait,
            ):
                mock_wait.return_value = True  # Resources become available

                def mock_spawn_with_resource_error(*args, **kwargs):
                    # First call fails, subsequent calls succeed
                    if mock_spawn_with_resource_error.call_count == 1:
                        raise error
                    return "test:1"

                mock_spawn_with_resource_error.call_count = 0

                with patch.object(monitor, "_execute_spawn_command", side_effect=mock_spawn_with_resource_error):
                    if hasattr(monitor, "_spawn_pm_with_retry"):
                        result = monitor._spawn_pm_with_retry("test:1", max_retries=3)

                        # Should eventually succeed
                        assert result == "test:1"

                        # Should wait for resources
                        assert mock_wait.called

                        # Should log resource issue
                        assert mock_log.called

                    else:
                        pytest.skip("_spawn_pm_with_retry not yet implemented")

    def test_exponential_backoff_retry_logic(self):
        """Test exponential backoff between retry attempts."""
        monitor = IdleMonitor(Mock())

        retry_times = []

        def mock_spawn_with_timing(*args, **kwargs):
            retry_times.append(time.time())
            if len(retry_times) < 3:  # Fail first 2 attempts
                raise Exception("Temporary failure")
            return "test:1"  # Succeed on 3rd attempt

        with patch("time.sleep") as mock_sleep:
            with patch.object(monitor, "_execute_spawn_command", side_effect=mock_spawn_with_timing):
                if hasattr(monitor, "_spawn_pm_with_exponential_backoff"):
                    result = monitor._spawn_pm_with_exponential_backoff("test:1")

                    # Should eventually succeed
                    assert result == "test:1"

                    # Check exponential backoff pattern
                    sleep_calls = [call[0][0] for call in mock_sleep.call_args_list]

                    # First retry: 1 second
                    # Second retry: 2 seconds
                    # Third retry: 4 seconds (but succeeds)
                    expected_pattern = [1, 2]  # Only first 2 retries have delays

                    assert len(sleep_calls) >= len(expected_pattern)
                    for i, expected_delay in enumerate(expected_pattern):
                        assert (
                            sleep_calls[i] == expected_delay
                        ), f"Expected {expected_delay}s delay, got {sleep_calls[i]}s"

                else:
                    pytest.skip("Exponential backoff not yet implemented")

    def test_max_retry_limit_enforcement(self):
        """Test that max retry limits are enforced."""
        monitor = IdleMonitor(Mock())

        attempt_count = 0

        def mock_spawn_always_fails(*args, **kwargs):
            nonlocal attempt_count
            attempt_count += 1
            raise Exception(f"Attempt {attempt_count} failed")

        with patch.object(monitor, "_escalate_recovery_failure") as mock_escalate:
            with patch.object(monitor, "_execute_spawn_command", side_effect=mock_spawn_always_fails):
                if hasattr(monitor, "_spawn_pm_with_retry"):
                    result = monitor._spawn_pm_with_retry("test:1", max_retries=5)

                    # Should fail after max retries
                    assert result is None or result is False

                    # Should have made exactly max_retries + 1 attempts
                    assert attempt_count == 6  # 1 initial + 5 retries

                    # Should escalate after exhausting retries
                    assert mock_escalate.called

                else:
                    pytest.skip("Retry limit enforcement not yet implemented")

    def test_network_timeout_handling(self):
        """Test handling of network/communication timeouts."""
        monitor = IdleMonitor(Mock())

        import subprocess

        def mock_spawn_with_timeout(*args, **kwargs):
            raise subprocess.TimeoutExpired("tmux-orc spawn", timeout=30)

        with (
            patch.object(monitor, "_log_timeout_error") as mock_log_timeout,
            patch.object(monitor, "_increase_timeout") as mock_increase_timeout,
        ):
            mock_increase_timeout.side_effect = [45, 60, 90]  # Increasing timeouts

            with patch.object(monitor, "_execute_spawn_command", side_effect=mock_spawn_with_timeout):
                if hasattr(monitor, "_spawn_pm_with_timeout_handling"):
                    monitor._spawn_pm_with_timeout_handling("test:1")

                    # Should handle timeout gracefully
                    assert mock_log_timeout.called
                    assert mock_increase_timeout.called

                    # Should try with increasing timeouts
                    assert mock_increase_timeout.call_count == 3

                else:
                    pytest.skip("Timeout handling not yet implemented")

    def test_concurrent_error_handling(self):
        """Test error handling under concurrent conditions."""
        monitor = IdleMonitor(Mock())

        error_log = []

        def mock_spawn_with_concurrent_error(*args, **kwargs):
            thread_id = threading.current_thread().ident
            error_log.append(f"Thread {thread_id} failed")
            raise Exception(f"Concurrent error from thread {thread_id}")

        def concurrent_recovery(thread_id):
            """Simulate concurrent recovery attempts."""
            try:
                if hasattr(monitor, "_spawn_pm_with_retry"):
                    result = monitor._spawn_pm_with_retry(f"test:{thread_id}", max_retries=2)
                    return ("success", result)
            except Exception as e:
                return ("error", str(e))

        with (
            patch.object(monitor, "_execute_spawn_command", side_effect=mock_spawn_with_concurrent_error),
            patch.object(monitor, "_log_error") as mock_log,
        ):
            # Launch multiple concurrent recovery attempts
            threads = []
            results = []

            for i in range(3):
                thread = threading.Thread(target=lambda i=i: results.append(concurrent_recovery(i)))
                threads.append(thread)
                thread.start()

            # Wait for all threads
            for thread in threads:
                thread.join()

            # All should have failed gracefully
            assert len(results) == 3
            for status, result in results:
                assert status in ["error", "success"]  # No crashes

            # Errors should be logged
            assert mock_log.called

    def test_context_preservation_error_handling(self):
        """Test error handling during context preservation."""
        monitor = IdleMonitor(Mock())

        context_errors = [
            FileNotFoundError("Context file not found"),
            PermissionError("Cannot read context file"),
            json.JSONDecodeError("Invalid JSON in context", "", 0),
            Exception("Context corruption detected"),
        ]

        for error in context_errors:
            with (
                patch.object(monitor, "_log_context_error") as mock_log,
                patch.object(monitor, "_use_default_context") as mock_default,
            ):
                mock_default.return_value = {"task": "default", "status": "unknown"}

                def mock_extract_context_with_error(*args, **kwargs):
                    raise error

                with patch.object(monitor, "_extract_pm_context", side_effect=mock_extract_context_with_error):
                    if hasattr(monitor, "_preserve_context_with_fallback"):
                        context = monitor._preserve_context_with_fallback("test:1")

                        # Should fall back to default context
                        assert context is not None
                        assert "task" in context

                        # Should log the error
                        assert mock_log.called

                        # Should use default context
                        assert mock_default.called

                    else:
                        pytest.skip("Context fallback handling not yet implemented")

    def test_team_notification_error_handling(self):
        """Test error handling during team notifications."""
        monitor = IdleMonitor(Mock())

        team_agents = [
            {"target": "test:2", "name": "dev1", "type": "developer"},
            {"target": "test:3", "name": "qa1", "type": "qa"},
            {"target": "test:4", "name": "review1", "type": "reviewer"},
        ]

        notification_results = []

        def mock_notify_with_errors(target, message):
            """Mock notification that fails for some agents."""
            if "dev1" in target:
                notification_results.append(("success", target))
                return True
            elif "qa1" in target:
                notification_results.append(("timeout", target))
                raise TimeoutError("Agent not responding")
            else:  # reviewer
                notification_results.append(("error", target))
                raise Exception("Notification failed")

        with (
            patch.object(monitor, "_notify_agent", side_effect=mock_notify_with_errors),
            patch.object(monitor, "_log_notification_error") as mock_log_error,
            patch.object(monitor, "_track_notification_failures") as mock_track,
        ):
            if hasattr(monitor, "_notify_team_with_error_handling"):
                monitor._notify_team_with_error_handling(team_agents, "PM has been recovered")

                # Should track both successes and failures
                assert len(notification_results) == 3

                success_count = len([r for r in notification_results if r[0] == "success"])
                error_count = len([r for r in notification_results if r[0] != "success"])

                assert success_count == 1  # Only dev1 succeeded
                assert error_count == 2  # qa1 and reviewer failed

                # Should log errors
                assert mock_log_error.called

                # Should track failures for retry
                assert mock_track.called

            else:
                pytest.skip("Team notification error handling not yet implemented")

    def test_recovery_state_corruption_handling(self):
        """Test handling of corrupted recovery state files."""
        monitor = IdleMonitor(Mock())

        state_file = Path("/tmp/test_recovery_state.json")

        # Create corrupted state file
        state_file.write_text("{ invalid json content }")

        try:
            with (
                patch.object(monitor, "_log_state_corruption") as mock_log,
                patch.object(monitor, "_reset_recovery_state") as mock_reset,
            ):
                if hasattr(monitor, "_load_recovery_state_safe"):
                    state = monitor._load_recovery_state_safe(state_file)

                    # Should handle corruption gracefully
                    assert state is None or isinstance(state, dict)

                    # Should log corruption
                    assert mock_log.called

                    # Should reset state
                    assert mock_reset.called

                else:
                    pytest.skip("Safe state loading not yet implemented")

        finally:
            if state_file.exists():
                state_file.unlink()

    def test_cascading_failure_prevention(self):
        """Test prevention of cascading failures during recovery."""
        monitor = IdleMonitor(Mock())

        failure_chain = []

        def track_failure(component, error):
            failure_chain.append({"component": component, "error": str(error)})

        with patch.object(monitor, "_isolate_failure", side_effect=track_failure):
            # Simulate multiple component failures
            def mock_spawn_failure(*args, **kwargs):
                track_failure("spawn", Exception("Spawn failed"))
                raise Exception("Spawn failed")

            def mock_context_failure(*args, **kwargs):
                track_failure("context", Exception("Context failed"))
                raise Exception("Context failed")

            def mock_notification_failure(*args, **kwargs):
                track_failure("notification", Exception("Notification failed"))
                raise Exception("Notification failed")

            with (
                patch.object(monitor, "_spawn_pm", side_effect=mock_spawn_failure),
                patch.object(monitor, "_extract_pm_context", side_effect=mock_context_failure),
                patch.object(monitor, "_notify_team", side_effect=mock_notification_failure),
            ):
                if hasattr(monitor, "_recover_pm_with_isolation"):
                    try:
                        result = monitor._recover_pm_with_isolation("test:1")

                        # Should isolate each failure
                        assert len(failure_chain) > 0

                        # Should not crash the entire system
                        assert result is not None  # Some result, even if failure

                    except Exception:
                        # If it raises, it should be a controlled exception
                        assert len(failure_chain) > 0, "Should have isolated failures first"

                else:
                    pytest.skip("Failure isolation not yet implemented")

    def test_error_escalation_hierarchy(self):
        """Test proper error escalation hierarchy."""
        monitor = IdleMonitor(Mock())

        escalation_log = []

        def mock_escalate(level, error, context=None):
            escalation_log.append({"level": level, "error": str(error), "context": context, "timestamp": time.time()})

        with patch.object(monitor, "_escalate_error", side_effect=mock_escalate):
            # Test different error types and their escalation levels
            error_scenarios = [
                ("temporary", Exception("Temporary network issue"), "warning"),
                ("resource", OSError("Out of memory"), "critical"),
                ("permission", PermissionError("Access denied"), "critical"),
                ("system", SystemError("System failure"), "emergency"),
            ]

            for error_type, error, expected_level in error_scenarios:
                escalation_log.clear()

                if hasattr(monitor, "_handle_error_with_escalation"):
                    monitor._handle_error_with_escalation(error_type, error)

                    # Should escalate to correct level
                    assert len(escalation_log) == 1
                    assert escalation_log[0]["level"] == expected_level

                else:
                    pytest.skip("Error escalation hierarchy not yet implemented")

    def test_recovery_timeout_handling(self):
        """Test handling of recovery operation timeouts."""
        monitor = IdleMonitor(Mock())

        with (
            patch.object(monitor, "_log_timeout") as mock_log_timeout,
            patch.object(monitor, "_abort_recovery") as mock_abort,
        ):

            def slow_recovery_operation(*args, **kwargs):
                time.sleep(0.1)  # Simulate slow operation
                raise TimeoutError("Recovery operation timed out")

            with patch.object(monitor, "_spawn_pm", side_effect=slow_recovery_operation):
                if hasattr(monitor, "_recover_pm_with_timeout"):
                    result = monitor._recover_pm_with_timeout("test:1", timeout=5)

                    # Should handle timeout gracefully
                    assert result is False or result is None

                    # Should log timeout
                    assert mock_log_timeout.called

                    # Should abort cleanly
                    assert mock_abort.called

                else:
                    pytest.skip("Recovery timeout handling not yet implemented")


class TestErrorHandlingIntegration:
    """Integration tests for error handling."""

    def setup_method(self):
        """Setup for integration tests."""
        self.error_test = ErrorHandlingRetryTest()
        self.error_test.setup_method()

    def teardown_method(self):
        """Cleanup after integration tests."""
        self.error_test.teardown_method()

    @pytest.mark.integration
    def test_comprehensive_error_scenario(self):
        """Test comprehensive error scenario with multiple failure points."""
        monitor = IdleMonitor(Mock())

        # This would be a full integration test with real tmux sessions
        # For now, test what we can with mocking

        error_sequence = []

        def track_error_handling(method_name, *args, **kwargs):
            error_sequence.append(method_name)

        # Test error handling methods exist
        error_methods = [
            "_handle_spawn_error",
            "_handle_context_error",
            "_handle_notification_error",
            "_escalate_recovery_failure",
        ]

        missing_methods = []
        for method in error_methods:
            if not hasattr(monitor, method):
                missing_methods.append(method)

        if missing_methods:
            pytest.skip(f"Missing error handling methods: {missing_methods}")

        print("✅ Error handling method structure exists")


if __name__ == "__main__":
    test = ErrorHandlingRetryTest()

    try:
        test.setup_method()

        print("Testing Error Handling and Retry Logic")
        print("=" * 50)

        # Test methods
        test_methods = [
            "test_spawn_command_permission_error",
            "test_resource_exhaustion_handling",
            "test_exponential_backoff_retry_logic",
            "test_max_retry_limit_enforcement",
            "test_network_timeout_handling",
            "test_concurrent_error_handling",
            "test_context_preservation_error_handling",
            "test_team_notification_error_handling",
            "test_recovery_state_corruption_handling",
            "test_cascading_failure_prevention",
            "test_error_escalation_hierarchy",
            "test_recovery_timeout_handling",
        ]

        for test_method in test_methods:
            print(f"\nTesting {test_method}...")

            try:
                method = getattr(test, test_method)
                method()
                print(f"✅ {test_method}: PASSED")

            except Exception as e:
                if "not yet implemented" in str(e) or "skip" in str(e).lower():
                    print(f"⏸️ {test_method}: SKIPPED - {e}")
                else:
                    print(f"❌ {test_method}: FAILED - {e}")

    finally:
        test.teardown_method()
        print("\nError handling test cleanup completed.")
